Workbook

Sheet Alle Items
A1: Item-ID | B1: Kompetenzbereich | C1: Nr. | D1: Teilbereich | E1: Stufe | F1: Stufenbezeichnung | G1: Itemtext | H1: Kurzfassung (Entwurf SZ, Kopie mit Fettdruck) | I1: Beispiele / Einleitung (einmal pro Teilbereich)
A2: 1.1-I | B2: 1. Berufsbezogenes Handeln | C2: 1.1 | D2: Berufliche Kommunikation | E2: I | F2: Einsteigen | G2: ='1. Berufsbezogenes Handeln'!D5 | H2: Ich kenne digitale Kanäle wie E-Mail oder Schulportal, nutze sie beruflich aber selten. | I2: ='1. Berufsbezogenes Handeln'!E4
A3: 1.1-II | B3: 1. Berufsbezogenes Handeln | C3: 1.1 | D3: Berufliche Kommunikation | E3: II | F3: Entdecken | G3: ='1. Berufsbezogenes Handeln'!D6 | H3: Ich probiere digitale Kanäle für den Austausch mit Lernenden, Eltern und Kollegium aus.
A4: 1.1-III | B4: 1. Berufsbezogenes Handeln | C4: 1.1 | D4: Berufliche Kommunikation | E4: III | F4: Anwenden | G4: ='1. Berufsbezogenes Handeln'!D7 | H4: Ich kommuniziere regelmässig digital und halte mich an vereinbarte Abläufe und Regeln.
A5: 1.1-IV | B5: 1. Berufsbezogenes Handeln | C5: 1.1 | D5: Berufliche Kommunikation | E5: IV | F5: Integrieren | G5: ='1. Berufsbezogenes Handeln'!D8 | H5: Ich wähle je nach Anliegen und Empfänger bewusst Kanal, Stil und Format.
A6: 1.1-V | B6: 1. Berufsbezogenes Handeln | C6: 1.1 | D6: Berufliche Kommunikation | E6: V | F6: Entwickeln | G6: ='1. Berufsbezogenes Handeln'!D9 | H6: Ich überprüfe mit dem Kollegium, wie wir mit Eltern und Lernenden digital kommunizieren.
A7: 1.1-VI | B7: 1. Berufsbezogenes Handeln | C7: 1.1 | D7: Berufliche Kommunikation | E7: VI | F7: Weitergeben | G7: ='1. Berufsbezogenes Handeln'!D10 | H7: Ich entwickle Kommunikationskonzepte mit und gebe sie über die Schule hinaus weiter.
A8: 1.2-I | B8: 1. Berufsbezogenes Handeln | C8: 1.2 | D8: Kollegiale Zusammenarbeit | E8: I | F8: Einsteigen | G8: ='1. Berufsbezogenes Handeln'!D13 | H8: Ich weiss, dass digitale Medien die Zusammenarbeit erleichtern, nutze sie aber selten. | I8: ='1. Berufsbezogenes Handeln'!E12
A9: 1.2-II | B9: 1. Berufsbezogenes Handeln | C9: 1.2 | D9: Kollegiale Zusammenarbeit | E9: II | F9: Entdecken | G9: ='1. Berufsbezogenes Handeln'!D14 | H9: Ich tausche mich mit Kolleginnen und Kollegen meiner Schule gelegentlich digital aus.
A10: 1.2-III | B10: 1. Berufsbezogenes Handeln | C10: 1.2 | D10: Kollegiale Zusammenarbeit | E10: III | F10: Anwenden | G10: ='1. Berufsbezogenes Handeln'!D15 | H10: Ich teile regelmässig Material digital und hole mir Ideen aus Online-Communities.
A11: 1.2-IV | B11: 1. Berufsbezogenes Handeln | C11: 1.2 | D11: Kollegiale Zusammenarbeit | E11: IV | F11: Integrieren | G11: ='1. Berufsbezogenes Handeln'!D16 | H11: Ich wähle passende Netzwerke bewusst aus, um Material gemeinsam zu erarbeiten.
A12: 1.2-V | B12: 1. Berufsbezogenes Handeln | C12: 1.2 | D12: Kollegiale Zusammenarbeit | E12: V | F12: Entwickeln | G12: ='1. Berufsbezogenes Handeln'!D17 | H12: Ich hole mir über berufliche Netzwerke Feedback zu meiner Praxis und entwickle mich weiter.
A13: 1.2-VI | B13: 1. Berufsbezogenes Handeln | C13: 1.2 | D13: Kollegiale Zusammenarbeit | E13: VI | F13: Weitergeben | G13: ='1. Berufsbezogenes Handeln'!D18 | H13: Ich unterstütze Lehrpersonen anderer Schulen über Online-Communities bei ihrer Weiterentwicklung.
A14: 1.3-I | B14: 1. Berufsbezogenes Handeln | C14: 1.3 | D14: Reflektiertes Handeln | E14: I | F14: Einsteigen | G14: ='1. Berufsbezogenes Handeln'!D21 | H14: Ich habe wenig Erfahrung und weiss noch nicht, wie ich mich weiterentwickeln kann. | I14: ='1. Berufsbezogenes Handeln'!E20
A15: 1.3-II | B15: 1. Berufsbezogenes Handeln | C15: 1.3 | D15: Reflektiertes Handeln | E15: II | F15: Entdecken | G15: ='1. Berufsbezogenes Handeln'!D22 | H15: Ich kenne meine Grenzen und suche nach Wegen, meine digitalen Kompetenzen zu erweitern.
A16: 1.3-III | B16: 1. Berufsbezogenes Handeln | C16: 1.3 | D16: Reflektiertes Handeln | E16: III | F16: Anwenden | G16: ='1. Berufsbezogenes Handeln'!D23 | H16: Ich experimentiere regelmässig mit digitalen Ansätzen und lerne dabei von Kolleginnen und Kollegen.
A17: 1.3-IV | B17: 1. Berufsbezogenes Handeln | C17: 1.3 | D17: Reflektiertes Handeln | E17: IV | F17: Integrieren | G17: ='1. Berufsbezogenes Handeln'!D24 | H17: Ich suche gezielt nach bewährten Praktiken und Kursen, um meinen Unterricht zu verbessern.
A18: 1.3-V | B18: 1. Berufsbezogenes Handeln | C18: 1.3 | D18: Reflektiertes Handeln | E18: V | F18: Entwickeln | G18: ='1. Berufsbezogenes Handeln'!D25 | H18: Ich verfolge neue Erkenntnisse und diskutiere die digitale Praxis unserer Schule im Kollegium.
A19: 1.3-VI | B19: 1. Berufsbezogenes Handeln | C19: 1.3 | D19: Reflektiertes Handeln | E19: VI | F19: Weitergeben | G19: ='1. Berufsbezogenes Handeln'!D26 | H19: Ich entwickle mit anderen, auch mit der Forschung, Strategien für eine bessere Bildungspraxis.
A20: 1.4-I | B20: 1. Berufsbezogenes Handeln | C20: 1.4 | D20: Kontinuierliche Weiterentwicklung | E20: I | F20: Einsteigen | G20: ='1. Berufsbezogenes Handeln'!D29 | H20: Ich weiss, dass ich mich online weiterbilden könnte, nutze dies aber kaum. | I20: ='1. Berufsbezogenes Handeln'!E28
A21: 1.4-II | B21: 1. Berufsbezogenes Handeln | C21: 1.4 | D21: Kontinuierliche Weiterentwicklung | E21: II | F21: Entdecken | G21: ='1. Berufsbezogenes Handeln'!D30 | H21: Ich suche gelegentlich online nach Informationen für mein Fach oder meinen Unterricht.
A22: 1.4-III | B22: 1. Berufsbezogenes Handeln | C22: 1.4 | D22: Kontinuierliche Weiterentwicklung | E22: III | F22: Anwenden | G22: ='1. Berufsbezogenes Handeln'!D31 | H22: Ich finde regelmässig passende Weiterbildungsangebote über das Internet.
A23: 1.4-IV | B23: 1. Berufsbezogenes Handeln | C23: 1.4 | D23: Kontinuierliche Weiterentwicklung | E23: IV | F23: Integrieren | G23: ='1. Berufsbezogenes Handeln'!D32 | H23: Ich wähle Online-Kurse und Materialien nach meinem Entwicklungsbedarf aus.
A24: 1.4-V | B24: 1. Berufsbezogenes Handeln | C24: 1.4 | D24: Kontinuierliche Weiterentwicklung | E24: V | F24: Entwickeln | G24: ='1. Berufsbezogenes Handeln'!D33 | H24: Ich berate Kolleginnen und Kollegen bei der Wahl von Online-Weiterbildungen.
A25: 1.4-VI | B25: 1. Berufsbezogenes Handeln | C25: 1.4 | D25: Kontinuierliche Weiterentwicklung | E25: VI | F25: Weitergeben | G25: ='1. Berufsbezogenes Handeln'!D34 | H25: Ich gestalte selbst Weiterbildungsangebote oder Materialien für andere Lehrpersonen.
A26: 2.1-I | B26: 2. Digitale Ressourcen | C26: 2.1 | D26: Auswählen digitaler Ressourcen | E26: I | F26: Einsteigen | G26: ='2. Digitale Ressourcen'!D5 | H26: Ich weiss, dass ich online nach Unterrichtsmaterial suchen kann, tue es aber selten. | I26: ='2. Digitale Ressourcen'!E4
A27: 2.1-II | B27: 2. Digitale Ressourcen | C27: 2.1 | D27: Auswählen digitaler Ressourcen | E27: II | F27: Entdecken | G27: ='2. Digitale Ressourcen'!D6 | H27: Ich finde digitales Material mit einfachen Suchstrategien, etwa über eine Bildungsplattform.
A28: 2.1-III | B28: 2. Digitale Ressourcen | C28: 2.1 | D28: Auswählen digitaler Ressourcen | E28: III | F28: Anwenden | G28: ='2. Digitale Ressourcen'!D7 | H28: Ich suche regelmässig auf verschiedenen Plattformen nach Material, das zu meiner Klasse passt.
A29: 2.1-IV | B29: 2. Digitale Ressourcen | C29: 2.1 | D29: Auswählen digitaler Ressourcen | E29: IV | F29: Integrieren | G29: ='2. Digitale Ressourcen'!D8 | H29: Ich wähle Material nach klaren Kriterien wie Qualität, Zuverlässigkeit und Lizenz aus.
A30: 2.1-V | B30: 2. Digitale Ressourcen | C30: 2.1 | D30: Auswählen digitaler Ressourcen | E30: V | F30: Entwickeln | G30: ='2. Digitale Ressourcen'!D9 | H30: Ich überprüfe meine Auswahlkriterien laufend und berate Kolleginnen und Kollegen.
A31: 2.1-VI | B31: 2. Digitale Ressourcen | C31: 2.1 | D31: Auswählen digitaler Ressourcen | E31: VI | F31: Weitergeben | G31: ='2. Digitale Ressourcen'!D10 | H31: Ich entwickle neue Strategien zur Auswahl digitaler Ressourcen und gebe sie weiter.
A32: 2.2-I | B32: 2. Digitale Ressourcen | C32: 2.2 | D32: Erstellen und Anpassen digitaler Ressourcen | E32: I | F32: Einsteigen | G32: ='2. Digitale Ressourcen'!D13 | H32: Ich weiss, dass ich Material digital erstellen kann, verzichte aber meist darauf. | I32: ='2. Digitale Ressourcen'!E12
A33: 2.2-II | B33: 2. Digitale Ressourcen | C33: 2.2 | D33: Erstellen und Anpassen digitaler Ressourcen | E33: II | F33: Entdecken | G33: ='2. Digitale Ressourcen'!D14 | H33: Ich erstelle erste einfache Materialien, etwa Texte, Präsentationen oder Bilder.
A34: 2.2-III | B34: 2. Digitale Ressourcen | C34: 2.2 | D34: Erstellen und Anpassen digitaler Ressourcen | E34: III | F34: Anwenden | G34: ='2. Digitale Ressourcen'!D15 | H34: Ich erstelle regelmässig digitale Materialien und passe sie an meine Lernenden an.
A35: 2.2-IV | B35: 2. Digitale Ressourcen | C35: 2.2 | D35: Erstellen und Anpassen digitaler Ressourcen | E35: IV | F35: Integrieren | G35: ='2. Digitale Ressourcen'!D16 | H35: Ich gestalte digitale Materialien bewusst nach Lernzielen und Gestaltungsprinzipien.
A36: 2.2-V | B36: 2. Digitale Ressourcen | C36: 2.2 | D36: Erstellen und Anpassen digitaler Ressourcen | E36: V | F36: Entwickeln | G36: ='2. Digitale Ressourcen'!D17 | H36: Ich entwickle komplexe interaktive Lernaktivitäten und teile mein Wissen im Kollegium.
A37: 2.2-VI | B37: 2. Digitale Ressourcen | C37: 2.2 | D37: Erstellen und Anpassen digitaler Ressourcen | E37: VI | F37: Weitergeben | G37: ='2. Digitale Ressourcen'!D18 | H37: Ich entwickle innovative Lernumgebungen mit neuen Technologien und gebe sie weiter.
A38: 2.3-I | B38: 2. Digitale Ressourcen | C38: 2.3 | D38: Organisieren, Schützen und Teilen digitaler Ressourcen | E38: I | F38: Einsteigen | G38: ='2. Digitale Ressourcen'!D21 | H38: Ich speichere digitale Materialien für mich und weiss, dass Urheberrechte gelten. | I38: ='2. Digitale Ressourcen'!E20
A39: 2.3-II | B39: 2. Digitale Ressourcen | C39: 2.3 | D39: Organisieren, Schützen und Teilen digitaler Ressourcen | E39: II | F39: Entdecken | G39: ='2. Digitale Ressourcen'!D22 | H39: Ich teile Material per Link oder Anhang und beachte dabei das Urheberrecht.
A40: 2.3-III | B40: 2. Digitale Ressourcen | C40: 2.3 | D40: Organisieren, Schützen und Teilen digitaler Ressourcen | E40: III | F40: Anwenden | G40: ='2. Digitale Ressourcen'!D23 | H40: Ich teile Material regelmässig und schütze sensible Daten wie Beurteilungen.
...

Sheet Info
A1: DigCompEdu Bavaria – Selbsteinschätzungswerkzeug: Itemtexte
A3: Quelle | B3: https://digcompedu.alp.dillingen.de/selbsteinschaetzung/ (ALP Dillingen), ausgelesen am 28.09.2026
A4: Umfang | B4: 6 Kompetenzbereiche, 22 Teilbereiche, je 6 Aussagen (Stufen I–VI) = 132 Items
A5: Stufen | B5: I–II Einsteigen/Entdecken · III–IV Anwenden/Integrieren · V–VI Entwickeln/Weitergeben
A6: Hinweis | B6: Die Stufenzuordnung ergibt sich aus der Reihenfolge der Antwortoptionen im Tool (1. Option = Stufe I usw.). Die Einzelbezeichnungen der Stufen (Einsteigen, Entdecken …) folgen dem DigCompEdu-Schema.
A7: Verknüpfung | B7: Die Itemtexte im Reiter «Alle Items» sind per Formel mit den Kapitelreitern verknüpft. Texte bitte nur in den Kapitelreitern (1.–6.) bearbeiten – «Alle Items» übernimmt Änderungen automatisch.
A9: Kurzfassung | B9: Entwurf vom 29.09.2026 in Spalte E der Kapitelreiter. «Alle Items» Spalte H enthält eine Kopie mit Fettdruck (kein Formelbezug, weil Formeln keine Formatierung übernehmen): Änderungen an der Kurzfassung bitte im Kapitelreiter vornehmen und bei Bedarf in «Alle Items» nachführen. Die Beispielzeile bzw. Einleitung pro Teilbereich steht in der Kopfzeile des Teilbereichs (Spalte E). Fett = das Konkrete der Stufe. Die Originaltexte in Spalte D bleiben unverändert.
A10: Regel 1 | B10: Ein Satz pro Stufe, etwa 10 bis 15 Wörter, ein Gedanke.
A11: Regel 2 | B11: Beispiele einmal pro Frage in einer Zeile über den Stufen, nicht in jeder Aussage.
A12: Regel 3 | B12: Feste Stufenlogik, freie Formulierung: Jede Stufe erfüllt in allen Fragen dasselbe Kriterium, die Worte passen sich dem Thema an.
A13: Regel 4 | B13: Das Konkrete fett, nicht ein Standardwort. Die Stufenlabels sorgen für die Wiedererkennung.
A15: Stufe I | B15: Einsteigen: Bewusstsein vorhanden, kaum eigene Praxis
A16: Stufe II | B16: Entdecken: erste Versuche, oft Herkömmliches digital umgesetzt
... A20: Stufe VI | B20: Weitergeben: Neues entwickeln, über die Schule hinaus weitergeben
A22: Wörter heute | B22: =SUM('1. Berufsbezogenes Handeln'!F4:F200)+SUM('2. Digitale Ressourcen'!F4:F200)+SUM('3. Lehren und Lernen'!F4:F200)+SUM('4. Lerndiagnose und Feedback'!F4:F200)+SUM('5. Schülerorientierung'!F4:F200)+SUM('6. Medienkompetenz d. Lernenden'!F4:F200)
A23: Wörter Kurzfassung | B23: =SUM('1. Berufsbezogenes Handeln'!G4:G200)+SUM('2. Digitale Ressourcen'!G4:G200)+SUM('3. Lehren und Lernen'!G4:G200)+SUM('4. Lerndiagnose und Feedback'!G4:G200)+SUM('5. Schülerorientierung'!G4:G200)+SUM('6. Medienkompetenz d. Lernenden'!G4:G200)
A24: Wörter Kurzfassung inkl. Beispielzeilen | B24: =SUMPRODUCT(LEN(TRIM('1. Berufsbezogenes Handeln'!E4:E200))-LEN(SUBSTITUTE(TRIM('1. Berufsbezogenes Handeln'!E4:E200)," ",""))+(LEN(TRIM('1. Berufsbezogenes Handeln'!E4:E200))>0))+SUMPRODUCT(LEN(TRIM('2. Digitale Ressourcen'!E4:E200))-LEN(SUBSTITUTE(TRIM('2. Digitale Ressourcen'!E4:E200)," ",""))+(LEN(TRIM('2. Digitale Ressourcen'!E4:E200))>0))+SUMPRODUCT(LEN(TRIM('3. Lehren und Lernen'!E4:E200))-LEN(SUBSTITUTE(TRIM('3. Lehren und Lernen'!E4:E200)," ",""))+(LEN(TRIM('3. Lehren und Lernen'!E4:E200))>0))+SUMPRODUCT(LEN(TRIM('4. Lerndiagnose und Feedback'!E4:E200))-LEN(SUBSTITUTE(TRIM('4. Lerndiagnose und Feedback'!E4:E200)," ",""))+(LEN(TRIM('4. Lerndiagnose und Feedback'!E4:E200))>0))+SUMPRODUCT(LEN(TRIM('5. Schülerorientierung'!E4:E200))-LEN(SUBSTITUTE(TRIM('5. Schülerorientierung'!E4:E200)," ",""))+(LEN(TRIM('5. Schülerorientierung'!E4:E200))>0))+SUMPRODUCT(LEN(TRIM('6. Medienkompetenz d. Lernenden'!E4:E200))-LEN(SUBSTITUTE(TRIM('6. Medienkompetenz d. Lernenden'!E4:E200)," ",""))+(LEN(TRIM('6. Medienkompetenz d. Lernenden'!E4:E200))>0))

Sheet 1. Berufsbezogenes Handeln
A1: 1. Berufsbezogenes Handeln
A3: Item-ID | B3: Stufe | C3: Stufenbezeichnung | D3: Itemtext | E3: Kurzfassung (Entwurf SZ) | F3: Wörter heute | G3: Wörter Kurzfassung
A4: 1.1 Berufliche Kommunikation | E4: Beispiele: E-Mail, Schulportal, Messenger der Schule, Elternkommunikation, Videokonferenz
A5: 1.1-I | B5: I | C5: Einsteigen | D5: Ich kenne digitale Medien wie E-Mail oder schulische Kommunikationsportale, nutze diese jedoch selten in beruflichen Kontexten. | E5: Ich kenne digitale Kanäle wie E-Mail oder Schulportal, nutze sie beruflich aber selten. | F5: =IF(LEN(TRIM(D5))=0,0,LEN(TRIM(D5))-LEN(SUBSTITUTE(TRIM(D5)," ",""))+1) | G5: =IF(LEN(TRIM(E5))=0,0,LEN(TRIM(E5))-LEN(SUBSTITUTE(TRIM(E5)," ",""))+1)
A6: 1.1-II | B6: II | C6: Entdecken | D6: Ich versuche digitale Medien adressatengerecht für die Kommunikation zu nutzen (z. B. mit Lernenden und Erziehungsberechtigten, im Kollegenkreis oder mit weiterem pädagogischem Personal). | E6: Ich probiere digitale Kanäle für den Austausch mit Lernenden, Eltern und Kollegium aus. | F6: =IF(LEN(TRIM(D6))=0,0,LEN(TRIM(D6))-LEN(SUBSTITUTE(TRIM(D6)," ",""))+1) | G6: =IF(LEN(TRIM(E6))=0,0,LEN(TRIM(E6))-LEN(SUBSTITUTE(TRIM(E6)," ",""))+1)
A7: 1.1-III | B7: III | C7: Anwenden | D7: Ich nutze geeignete digitale Kommunikationskanäle und kommuniziere sprachsensibel. Dabei berücksichtige ich Nutzungsbedingungen und vereinbarte Kommunikationsabläufe. | E7: Ich kommuniziere regelmässig digital und halte mich an vereinbarte Abläufe und Regeln. | F7: =IF(LEN(TRIM(D7))=0,0,LEN(TRIM(D7))-LEN(SUBSTITUTE(TRIM(D7)," ",""))+1) | G7: =IF(LEN(TRIM(E7))=0,0,LEN(TRIM(E7))-LEN(SUBSTITUTE(TRIM(E7)," ",""))+1)
A8: 1.1-IV | B8: IV | C8: Integrieren | D8: Ich wähle aus einem breiten Repertoire an Kommunikationskanälen einen angemessenen Kanal, Stil und das Format für einen bestimmten Kommunikationszweck und -kontext aus. | E8: Ich wähle je nach Anliegen und Empfänger bewusst Kanal, Stil und Format. | F8: =IF(LEN(TRIM(D8))=0,0,LEN(TRIM(D8))-LEN(SUBSTITUTE(TRIM(D8)," ",""))+1) | G8: =IF(LEN(TRIM(E8))=0,0,LEN(TRIM(E8))-LEN(SUBSTITUTE(TRIM(E8)," ",""))+1)
A9: 1.1-V | B9: V | C9: Entwickeln | D9: Ich reflektiere, bewerte und diskutiere im Kollegenkreis die Art und Weise, wie digitale Medien effektiv für die schulische Kommunikation genutzt werden. Ich nutze digitale Medien, um schulorganisatorische Verfahren für Lernende und/oder Erziehungsberechtigte transparent zu machen und ihnen zu ermöglichen, informierte Entscheidungen zu treffen. | E9: Ich überprüfe mit dem Kollegium, wie wir mit Eltern und Lernenden digital kommunizieren. | F9: =IF(LEN(TRIM(D9))=0,0,LEN(TRIM(D9))-LEN(SUBSTITUTE(TRIM(D9)," ",""))+1) | G9: =IF(LEN(TRIM(E9))=0,0,LEN(TRIM(E9))-LEN(SUBSTITUTE(TRIM(E9)," ",""))+1)
A10: 1.1-VI | B10: VI | C10: Weitergeben | D10: Ich trage zur Entwicklung innovativer Konzepte und Strategien für den verantwortungsvollen Einsatz digitaler Technologien für die Kommunikation bei und multipliziere diese auch über die eigene Schule hinaus. | E10: Ich entwickle Kommunikationskonzepte mit und gebe sie über die Schule hinaus weiter. | F10: =IF(LEN(TRIM(D10))=0,0,LEN(TRIM(D10))-LEN(SUBSTITUTE(TRIM(D10)," ",""))+1) | G10: =IF(LEN(TRIM(E10))=0,0,LEN(TRIM(E10))-LEN(SUBSTITUTE(TRIM(E10)," ",""))+1)
A12: 1.2 Kollegiale Zusammenarbeit | E12: Beispiele: gemeinsame Ablage, Online-Plattform, Videokonferenz, Online-Communities für Lehrpersonen
A13: 1.2-I | B13: I | C13: Einsteigen | D13: Ich bin mir bewusst, dass digitale Medien die Zusammenarbeit mit Kolleginnen und Kollegen - auch außerhalb meiner Schule - unterstützen, nutze diese jedoch selten (z. B. kollaborative Online-Plattformen oder Videokonferenzwerkzeuge). | E13: Ich weiss, dass digitale Medien die Zusammenarbeit erleichtern, nutze sie aber selten. | F13: =IF(LEN(TRIM(D13))=0,0,LEN(TRIM(D13))-LEN(SUBSTITUTE(TRIM(D13)," ",""))+1) | G13: =IF(LEN(TRIM(E13))=0,0,LEN(TRIM(E13))-LEN(SUBSTITUTE(TRIM(E13)," ",""))+1)
A14: 1.2-II | B14: II | C14: Entdecken | D14: Ich versuche mit digitalen Medien mit Kolleginnen und Kollegen an meiner Schule zusammenzuarbeiten (z. B. um Inhalte, Wissen oder Meinungen auszutauschen). | E14: Ich tausche mich mit Kolleginnen und Kollegen meiner Schule gelegentlich digital aus. | F14: =IF(LEN(TRIM(D14))=0,0,LEN(TRIM(D14))-LEN(SUBSTITUTE(TRIM(D14)," ",""))+1) | G14: =IF(LEN(TRIM(E14))=0,0,LEN(TRIM(E14))-LEN(SUBSTITUTE(TRIM(E14)," ",""))+1)
A15: 1.2-III | B15: III | C15: Anwenden | D15: Ich nutze Online-Communities (z. B. Twitter oder Internetforen für Lehrkräfte), um neue pädagogische Ressourcen oder Methoden zu entdecken. Auch nutze ich digitale Medien zum Teilen von Materialien und zum Austausch von Wissen und Meinungen in und außerhalb meiner Schule. | E15: Ich teile regelmässig Material digital und hole mir Ideen aus Online-Communities. | F15: =IF(LEN(TRIM(D15))=0,0,LEN(TRIM(D15))-LEN(SUBSTITUTE(TRIM(D15)," ",""))+1) | G15: =IF(LEN(TRIM(E15))=0,0,LEN(TRIM(E15))-LEN(SUBSTITUTE(TRIM(E15)," ",""))+1)
A16: 1.2-IV | B16: IV | C16: Integrieren | D16: Ich wähle aktiv Online-Communities aus, um Ideen und digitale Ressourcen auszutauschen und zu erarbeiten (z. B. mebis-TeachSHARE ). | E16: Ich wähle passende Netzwerke bewusst aus, um Material gemeinsam zu erarbeiten. | F16: =IF(LEN(TRIM(D16))=0,0,LEN(TRIM(D16))-LEN(SUBSTITUTE(TRIM(D16)," ",""))+1) | G16: =IF(LEN(TRIM(E16))=0,0,LEN(TRIM(E16))-LEN(SUBSTITUTE(TRIM(E16)," ",""))+1)
A17: 1.2-V | B17: V | C17: Entwickeln | D17: Durch die Nutzung beruflicher Kooperationsnetzwerke entwickle ich meine berufliche Praxis und meine Kompetenzen weiter. Dadurch erhalte ich Feedback zu pädagogischen Konzepten und Unterrichtsideen. | E17: Ich hole mir über berufliche Netzwerke Feedback zu meiner Praxis und entwickle mich weiter. | F17: =IF(LEN(TRIM(D17))=0,0,LEN(TRIM(D17))-LEN(SUBSTITUTE(TRIM(D17)," ",""))+1) | G17: =IF(LEN(TRIM(E17))=0,0,LEN(TRIM(E17))-LEN(SUBSTITUTE(TRIM(E17)," ",""))+1)
A18: 1.2-VI | B18: VI | C18: Weitergeben | D18: Mit Hilfe von Online-Communities trage ich zur innovativen Weiterentwicklung pädagogischer Praktiken bei. Dabei fördere und unterstütze ich Lehrkräfte auch außerhalb des eigenen Kollegiums bei der Weiterentwicklung ihrer digitalen und pädagogischen Kompetenzen. | E18: Ich unterstütze Lehrpersonen anderer Schulen über Online-Communities bei ihrer Weiterentwicklung. | F18: =IF(LEN(TRIM(D18))=0,0,LEN(TRIM(D18))-LEN(SUBSTITUTE(TRIM(D18)," ",""))+1) | G18: =IF(LEN(TRIM(E18))=0,0,LEN(TRIM(E18))-LEN(SUBSTITUTE(TRIM(E18)," ",""))+1)
A20: 1.3 Reflektiertes Handeln | E20: Worum es geht: die eigene digitale Praxis reflektieren und gezielt weiterentwickeln.
A21: 1.3-I | B21: I | C21: Einsteigen | D21: Ich bin mir bewusst, dass digitale Medien im schulischen Kontext eingesetzt werden können. Jedoch habe ich hierin kaum Erfahrung und bin mir über die Möglichkeiten noch im Unklaren, wie ich mich hier weiterentwickeln kann. | E21: Ich habe wenig Erfahrung und weiss noch nicht, wie ich mich weiterentwickeln kann. | F21: =IF(LEN(TRIM(D21))=0,0,LEN(TRIM(D21))-LEN(SUBSTITUTE(TRIM(D21)," ",""))+1) | G21: =IF(LEN(TRIM(E21))=0,0,LEN(TRIM(E21))-LEN(SUBSTITUTE(TRIM(E21)," ",""))+1)
A22: 1.3-II | B22: II | C22: Entdecken | D22: Ich suche nach Wegen, meine medienbezogenen Lehrkompetenzen weiterzuentwickeln. Dabei bin ich mir der Grenzen meiner eigenen digitalen Kompetenz wie auch notwendiger individueller Entwicklungsbereiche bewusst. | E22: Ich kenne meine Grenzen und suche nach Wegen, meine digitalen Kompetenzen zu erweitern. | F22: =IF(LEN(TRIM(D22))=0,0,LEN(TRIM(D22))-LEN(SUBSTITUTE(TRIM(D22)," ",""))+1) | G22: =IF(LEN(TRIM(E22))=0,0,LEN(TRIM(E22))-LEN(SUBSTITUTE(TRIM(E22)," ",""))+1)
A23: 1.3-III | B23: III | C23: Anwenden | D23: Ich nutze digitale Medien bewusst in verschiedenen schulischen Kontexten und zu unterschiedlichen Zwecken, um mit zeitgemäßen pädagogischen Ansätzen zu experimentieren. Dabei möchte ich meine medienbezogenen Lehrkompetenzen durch Erproben und Peer-Learning weiterentwickeln und verbessern. | E23: Ich experimentiere regelmässig mit digitalen Ansätzen und lerne dabei von Kolleginnen und Kollegen. | F23: =IF(LEN(TRIM(D23))=0,0,LEN(TRIM(D23))-LEN(SUBSTITUTE(TRIM(D23)," ",""))+1) | G23: =IF(LEN(TRIM(E23))=0,0,LEN(TRIM(E23))-LEN(SUBSTITUTE(TRIM(E23)," ",""))+1)
A24: 1.3-IV | B24: IV | C24: Integrieren | D24: Ich analysiere und diskutiere mit Kolleginnen und Kollegen, wie die Nutzung von digitalen Medien zur Erneuerung und Verbesserung der Unterrichtspraxis realisiert werden kann. Ich suche aktiv nach bewährten Praktiken, Kursen oder anderen Ratschlägen, um meine eigenen digitalen pädagogischen Konzepte zu verbessern und digitale Kompetenzen auszuweiten. | E24: Ich suche gezielt nach bewährten Praktiken und Kursen, um meinen Unterricht zu verbessern. | F24: =IF(LEN(TRIM(D24))=0,0,LEN(TRIM(D24))-LEN(SUBSTITUTE(TRIM(D24)," ",""))+1) | G24: =IF(LEN(TRIM(E24))=0,0,LEN(TRIM(E24))-LEN(SUBSTITUTE(TRIM(E24)," ",""))+1)
A25: 1.3-V | B25: V | C25: Entwickeln | D25: Ich unterstütze Kolleginnen und Kollegen dabei, ihre digitalen Kompetenzen weiterzuentwickeln. Ich informiere mich regelmäßig, z. B. in Fachzeitschriften oder im Internet über aktuelle wissenschaftliche Erkenntnisse und übertrage diese in meine Praxis. Zudem bewerte, reflektiere und diskutiere ich über Konzepte und Praxis der Schule hinsichtlich der Nutzung digitaler Medien (z.B. Teilnahme an Kongressen und Organisation von SchiLFS) | E25: Ich verfolge neue Erkenntnisse und diskutiere die digitale Praxis unserer Schule im Kollegium. | F25: =IF(LEN(TRIM(D25))=0,0,LEN(TRIM(D25))-LEN(SUBSTITUTE(TRIM(D25)," ",""))+1) | G25: =IF(LEN(TRIM(E25))=0,0,LEN(TRIM(E25))-LEN(SUBSTITUTE(TRIM(E25)," ",""))+1)
A26: 1.3-VI | B26: VI | C26: Weitergeben | D26: Mit Hilfe digitaler Medien trage ich dazu bei, individuell oder gemeinsam mit Kolleginnen und Kollegen eine Strategie zur Verbesserung der Bildungspraxis zu entwickeln. Ich reflektiere und evaluiere mit Kolleginnen und Kollegen und/oder Wissenschaftlerinnen und Wissenschaftlern verschiedene digitale Praktiken, Methoden und Strategien mit dem Ziel, innovative Konzepte zu entwickeln. (z.B. Mitwirkung an Kongressen oder Barcamps) | E26: Ich entwickle mit anderen, auch mit der Forschung, Strategien für eine bessere Bildungspraxis. | F26: =IF(LEN(TRIM(D26))=0,0,LEN(TRIM(D26))-LEN(SUBSTITUTE(TRIM(D26)," ",""))+1) | G26: =IF(LEN(TRIM(E26))=0,0,LEN(TRIM(E26))-LEN(SUBSTITUTE(TRIM(E26)," ",""))+1)
A28: 1.4 Kontinuierliche Weiterentwicklung | E28: Beispiele: Online-Kurse, Webinare, Erklärvideos, Fachblogs, Bildungsportale
A29: 1.4-I | B29: I | C29: Einsteigen | D29: Ich bin mir bewusst, dass ich mit Hilfe des Internets mein fachspezifisches oder pädagogisches Wissen aktualisieren oder meine Fähigkeiten erweitern kann. | E29: Ich weiss, dass ich mich online weiterbilden könnte, nutze dies aber kaum. | F29: =IF(LEN(TRIM(D29))=0,0,LEN(TRIM(D29))-LEN(SUBSTITUTE(TRIM(D29)," ",""))+1) | G29: =IF(LEN(TRIM(E29))=0,0,LEN(TRIM(E29))-LEN(SUBSTITUTE(TRIM(E29)," ",""))+1)
A30: 1.4-II | B30: II | C30: Entdecken | D30: Ich suche nach Wegen, mit Hilfe des Internets mein fachspezifisches oder pädagogisches Wissen zu aktualisieren. (z.B. Onlineportale, Edu-Blogs, Themenseiten des ISB) | E30: Ich suche gelegentlich online nach Informationen für mein Fach oder meinen Unterricht. | F30: =IF(LEN(TRIM(D30))=0,0,LEN(TRIM(D30))-LEN(SUBSTITUTE(TRIM(D30)," ",""))+1) | G30: =IF(LEN(TRIM(E30))=0,0,LEN(TRIM(E30))-LEN(SUBSTITUTE(TRIM(E30)," ",""))+1)
A31: 1.4-III | B31: III | C31: Anwenden | D31: Ich nutze das Internet, um gezielt passende Fort- und Weiterbildungsangebote und andere Chancen für die berufliche Weiterentwicklung zu identifizieren. (z. B. Identifizierung geeigneter Fortbildungsveranstaltungen) | E31: Ich finde regelmässig passende Weiterbildungsangebote über das Internet. | F31: =IF(LEN(TRIM(D31))=0,0,LEN(TRIM(D31))-LEN(SUBSTITUTE(TRIM(D31)," ",""))+1) | G31: =IF(LEN(TRIM(E31))=0,0,LEN(TRIM(E31))-LEN(SUBSTITUTE(TRIM(E31)," ",""))+1)
A32: 1.4-IV | B32: IV | C32: Integrieren | D32: Ich wähle zielgerichtet Online-Fortbildungen (z. B. eSessions) oder digitales Weiterbildungsmaterial und Video-Tutorials als Quelle für meine berufliche Weiterentwicklung aus. | E32: Ich wähle Online-Kurse und Materialien nach meinem Entwicklungsbedarf aus. | F32: =IF(LEN(TRIM(D32))=0,0,LEN(TRIM(D32))-LEN(SUBSTITUTE(TRIM(D32)," ",""))+1) | G32: =IF(LEN(TRIM(E32))=0,0,LEN(TRIM(E32))-LEN(SUBSTITUTE(TRIM(E32)," ",""))+1)
A33: 1.4-V | B33: V | C33: Entwickeln | D33: Ich berate meine Kolleginnen und Kollegen bei der Wahl von Online-Fortbildungsmöglichkeiten. Dazu sichte ich eine Vielzahl von Angeboten und wähle diejenigen aus, die meinen Weiterentwicklungsbedürfnissen und ggf. denen meiner Kolleginnen und Kollegen am besten entsprechen. Ich nehme aktiv an Online-Fortbildungen teil und trage durch gezieltes Feedback zu deren Verbesserung bei. | E33: Ich berate Kolleginnen und Kollegen bei der Wahl von Online-Weiterbildungen. | F33: =IF(LEN(TRIM(D33))=0,0,LEN(TRIM(D33))-LEN(SUBSTITUTE(TRIM(D33)," ",""))+1) | G33: =IF(LEN(TRIM(E33))=0,0,LEN(TRIM(E33))-LEN(SUBSTITUTE(TRIM(E33)," ",""))+1)
A34: 1.4-VI | B34: VI | C34: Weitergeben | D34: Ich fördere Kolleginnen und Kollegen mit Hilfe digitaler Technologien (z. B. im Rahmen von Fortbildungen, durch persönliche Blogs oder indem ich für sie neues digitales Fortbildungsmaterial entwickle). | E34: Ich gestalte selbst Weiterbildungsangebote oder Materialien für andere Lehrpersonen. | F34: =IF(LEN(TRIM(D34))=0,0,LEN(TRIM(D34))-LEN(SUBSTITUTE(TRIM(D34)," ",""))+1) | G34: =IF(LEN(TRIM(E34))=0,0,LEN(TRIM(E34))-LEN(SUBSTITUTE(TRIM(E34)," ",""))+1)

Sheet 2. Digitale Ressourcen
A1: 2. Digitale Ressourcen
A3: Item-ID | B3: Stufe | C3: Stufenbezeichnung | D3: Itemtext | E3: Kurzfassung (Entwurf SZ) | F3: Wörter heute | G3: Wörter Kurzfassung
A4: 2.1 Auswählen digitaler Ressourcen | E4: Beispiele: Arbeitsblätter, Lernvideos, Online-Quiz, Bildungsplattformen, offene Lernmaterialien (OER)
A5: 2.1-I | B5: I | C5: Einsteigen | D5: Ich bin mir bewusst, dass ich online nach Lehr- und Lernressourcen suchen kann, nutze die Möglichkeit jedoch nicht oder nur selten (z.B. Arbeitsmaterial, Onlinequizze oder Videos). | E5: Ich weiss, dass ich online nach Unterrichtsmaterial suchen kann, tue es aber selten. | F5: =IF(LEN(TRIM(D5))=0,0,LEN(TRIM(D5))-LEN(SUBSTITUTE(TRIM(D5)," ",""))+1) | G5: =IF(LEN(TRIM(E5))=0,0,LEN(TRIM(E5))-LEN(SUBSTITUTE(TRIM(E5)," ",""))+1)
A6: 2.1-II | B6: II | C6: Entdecken | D6: Ich nutze einfache Internet-Suchstrategien, um digitale Lehr- und Lernressourcen zum Beispiel auf Bildungsplattformen wie mebis zu finden. | E6: Ich finde digitales Material mit einfachen Suchstrategien, etwa über eine Bildungsplattform. | F6: =IF(LEN(TRIM(D6))=0,0,LEN(TRIM(D6))-LEN(SUBSTITUTE(TRIM(D6)," ",""))+1) | G6: =IF(LEN(TRIM(E6))=0,0,LEN(TRIM(E6))-LEN(SUBSTITUTE(TRIM(E6)," ",""))+1)
A7: 2.1-III | B7: III | C7: Anwenden | D7: Ich identifiziere und verwende geeignete Online-Werkzeuge und Bildungsplattformen, um nach vielfältigen digitalen Ressourcen zu suchen, die dem Bildungsbedarf meiner Lernenden entsprechen (z. B. mebis). | E7: Ich suche regelmässig auf verschiedenen Plattformen nach Material, das zu meiner Klasse passt. | F7: =IF(LEN(TRIM(D7))=0,0,LEN(TRIM(D7))-LEN(SUBSTITUTE(TRIM(D7)," ",""))+1) | G7: =IF(LEN(TRIM(E7))=0,0,LEN(TRIM(E7))-LEN(SUBSTITUTE(TRIM(E7)," ",""))+1)
A8: 2.1-IV | B8: IV | C8: Integrieren | D8: Ich wähle digitale Ressourcen auf der Grundlage komplexer Kriterien aus und entwickle meine Suchkriterien mit Blick auf den intendierten Kompetenzerwerb weiter, um meine spezifischen Lehr- und Lernziele zu erfüllen (z. B. Bildungswert, Relevanz, Zuverlässigkeit, Gültigkeit, Qualität, Lizenzierung). | E8: Ich wähle Material nach klaren Kriterien wie Qualität, Zuverlässigkeit und Lizenz aus. | F8: =IF(LEN(TRIM(D8))=0,0,LEN(TRIM(D8))-LEN(SUBSTITUTE(TRIM(D8)," ",""))+1) | G8: =IF(LEN(TRIM(E8))=0,0,LEN(TRIM(E8))-LEN(SUBSTITUTE(TRIM(E8)," ",""))+1)
A9: 2.1-V | B9: V | C9: Entwickeln | D9: Ich reflektiere und bewerte meine Suchergebnisse umfassend und passe meine Auswahlkriterien ggf. neu und flexibel an (z. B. Prüfung von Genauigkeit und Neutralität). Außerdem berate ich meine Kolleginnen und Kollegen. | E9: Ich überprüfe meine Auswahlkriterien laufend und berate Kolleginnen und Kollegen. | F9: =IF(LEN(TRIM(D9))=0,0,LEN(TRIM(D9))-LEN(SUBSTITUTE(TRIM(D9)," ",""))+1) | G9: =IF(LEN(TRIM(E9))=0,0,LEN(TRIM(E9))-LEN(SUBSTITUTE(TRIM(E9)," ",""))+1)
A10: 2.1-VI | B10: VI | C10: Weitergeben | D10: Ich entwickle und multipliziere innovative Strategien zur Auswahl, Identifizierung und Auswertung digitaler Ressourcen. | E10: Ich entwickle neue Strategien zur Auswahl digitaler Ressourcen und gebe sie weiter. | F10: =IF(LEN(TRIM(D10))=0,0,LEN(TRIM(D10))-LEN(SUBSTITUTE(TRIM(D10)," ",""))+1) | G10: =IF(LEN(TRIM(E10))=0,0,LEN(TRIM(E10))-LEN(SUBSTITUTE(TRIM(E10)," ",""))+1)
A12: 2.2 Erstellen und Anpassen digitaler Ressourcen | E12: Beispiele: Präsentationen, interaktive Übungen, Erklärvideos, Lernpfade, digitale Lernumgebungen
A13: 2.2-I | B13: I | C13: Einsteigen | D13: Ich bin mir der Tatsache bewusst, dass ich bestehende Ressourcen in digitaler Form erstellen oder anpassen kann, verzichte aber meist darauf (z. B. Textverarbeitung, Bilder, Fotos, Audio, Video). | E13: Ich weiss, dass ich Material digital erstellen kann, verzichte aber meist darauf. | F13: =IF(LEN(TRIM(D13))=0,0,LEN(TRIM(D13))-LEN(SUBSTITUTE(TRIM(D13)," ",""))+1) | G13: =IF(LEN(TRIM(E13))=0,0,LEN(TRIM(E13))-LEN(SUBSTITUTE(TRIM(E13)," ",""))+1)
A14: 2.2-II | B14: II | C14: Entdecken | D14: Ich entdecke für mich neue digitale Ressourcen und habe bereits versucht, eigene Ressourcen mit Hilfe von einfachen Tools zu erstellen oder anzupassen (z. B. Textverarbeitung, Bilder, Tabellen, Präsentationen, Audio- oder Videodateien). | E14: Ich erstelle erste einfache Materialien, etwa Texte, Präsentationen oder Bilder. | F14: =IF(LEN(TRIM(D14))=0,0,LEN(TRIM(D14))-LEN(SUBSTITUTE(TRIM(D14)," ",""))+1) | G14: =IF(LEN(TRIM(E14))=0,0,LEN(TRIM(E14))-LEN(SUBSTITUTE(TRIM(E14)," ",""))+1)
A15: 2.2-III | B15: III | C15: Anwenden | D15: Ich identifiziere und verwende geeignete digitale Tools, um Ressourcen zu erstellen und passe sie ggf. sach-und situationsgerecht an, um den Bedürfnissen der Lernenden zu entsprechen (z. B. interaktive Texte, Multimedia-Präsentationen, Quizze, Spiele, Online-Aktivitäten und Unterricht). | E15: Ich erstelle regelmässig digitale Materialien und passe sie an meine Lernenden an. | F15: =IF(LEN(TRIM(D15))=0,0,LEN(TRIM(D15))-LEN(SUBSTITUTE(TRIM(D15)," ",""))+1) | G15: =IF(LEN(TRIM(E15))=0,0,LEN(TRIM(E15))-LEN(SUBSTITUTE(TRIM(E15)," ",""))+1)
A16: 2.2-IV | B16: IV | C16: Integrieren | D16: Ich wende Gestaltungsprinzipien und -prozesse an, um digitale Ressourcen zu schaffen oder systematisch anzupassen, damit sie den Lehr- und Lernzielen entsprechen (z.B. Entwerfen eines Onlinelernspiels, digitale Lernumgebungen, Erklärvideos). | E16: Ich gestalte digitale Materialien bewusst nach Lernzielen und Gestaltungsprinzipien. | F16: =IF(LEN(TRIM(D16))=0,0,LEN(TRIM(D16))-LEN(SUBSTITUTE(TRIM(D16)," ",""))+1) | G16: =IF(LEN(TRIM(E16))=0,0,LEN(TRIM(E16))-LEN(SUBSTITUTE(TRIM(E16)," ",""))+1)
A17: 2.2-V | B17: V | C17: Entwickeln | D17: Ich erstelle Konzepte für komplexe und interaktive digitale Lernaktivitäten und/oder passe diese an (z. B. interaktive Arbeitsbögen, Lernaktivitäten wie Wikis, Blogs, Lernpfade). Ich reflektiere kritisch, inwiefern sich verschiedene Methoden für die Erstellung digitaler Ressourcen eignen und gebe mein Wissen im Kollegenkreis weiter. | E17: Ich entwickle komplexe interaktive Lernaktivitäten und teile mein Wissen im Kollegium. | F17: =IF(LEN(TRIM(D17))=0,0,LEN(TRIM(D17))-LEN(SUBSTITUTE(TRIM(D17)," ",""))+1) | G17: =IF(LEN(TRIM(E17))=0,0,LEN(TRIM(E17))-LEN(SUBSTITUTE(TRIM(E17)," ",""))+1)
A18: 2.2-VI | B18: VI | C18: Weitergeben | D18: Ich entwickle und multipliziere komplexe und innovative digitale Ressourcen für Lehr-/Lernkontexte (z. B.digitale Lernumgebungen mit 3D-Animationen) unter Berücksichtigung neuester technischer Entwicklungen. | E18: Ich entwickle innovative Lernumgebungen mit neuen Technologien und gebe sie weiter. | F18: =IF(LEN(TRIM(D18))=0,0,LEN(TRIM(D18))-LEN(SUBSTITUTE(TRIM(D18)," ",""))+1) | G18: =IF(LEN(TRIM(E18))=0,0,LEN(TRIM(E18))-LEN(SUBSTITUTE(TRIM(E18)," ",""))+1)
A20: 2.3 Organisieren, Schützen und Teilen digitaler Ressourcen | E20: Beispiele: Ablage in der Cloud, Links teilen, Lernplattform, Urheberrecht, Schutz von Personendaten
A21: 2.3-I | B21: I | C21: Einsteigen | D21: Ich speichere und verwalte digitale Ressourcen, wie z. B. Arbeitsmaterial, Fotos oder Videos zur eigenen Verwendung. Ich bin mir der Tatsache bewusst, dass einige der im Internet verbreiteten Ressourcen dem Urheberrecht unterliegen. | E21: Ich speichere digitale Materialien für mich und weiss, dass Urheberrechte gelten. | F21: =IF(LEN(TRIM(D21))=0,0,LEN(TRIM(D21))-LEN(SUBSTITUTE(TRIM(D21)," ",""))+1) | G21: =IF(LEN(TRIM(E21))=0,0,LEN(TRIM(E21))-LEN(SUBSTITUTE(TRIM(E21)," ",""))+1)
A22: 2.3-II | B22: II | C22: Entdecken | D22: Ich teile Unterrichtsmaterialien (z. B. Texte und interaktive Aufgaben) unter Beachtung des Urheberrechts als Anhang einer Nachricht oder durch die Weitergabe von Links. | E22: Ich teile Material per Link oder Anhang und beachte dabei das Urheberrecht. | F22: =IF(LEN(TRIM(D22))=0,0,LEN(TRIM(D22))-LEN(SUBSTITUTE(TRIM(D22)," ",""))+1) | G22: =IF(LEN(TRIM(E22))=0,0,LEN(TRIM(E22))-LEN(SUBSTITUTE(TRIM(E22)," ",""))+1)
A23: 2.3-III | B23: III | C23: Anwenden | D23: Ich teile verantwortungsvoll Unterrichtsmaterialien (z. B. Verschlüsselung von Texten, Videos, Lernspiele und Aufgaben) im Rahmen des digital gestützten Lernens und schütze sensible Inhalte wie Leistungserhebungen oder Berichte der Lehrkräfte effektiv. | E23: Ich teile Material regelmässig und schütze sensible Daten wie Beurteilungen. | F23: =IF(LEN(TRIM(D23))=0,0,LEN(TRIM(D23))-LEN(SUBSTITUTE(TRIM(D23)," ",""))+1) | G23: =IF(LEN(TRIM(E23))=0,0,LEN(TRIM(E23))-LEN(SUBSTITUTE(TRIM(E23)," ",""))+1)
A24: 2.3-IV | B24: IV | C24: Integrieren | D24: Ich teile Ressourcen (z. B. Texte, Videos, Lernspiele und interaktive Aufgaben) professionell, indem ich sie in digitale Lernumgebungen einbette. Ich schütze persönliche und sensible Daten effektiv. Ich kennzeichne Ressourcen, die dem Urheberrecht unterliegen, richtig. | E24: Ich stelle Material geordnet auf einer Lernplattform bereit und kennzeichne Quellen korrekt. | F24: =IF(LEN(TRIM(D24))=0,0,LEN(TRIM(D24))-LEN(SUBSTITUTE(TRIM(D24)," ",""))+1) | G24: =IF(LEN(TRIM(E24))=0,0,LEN(TRIM(E24))-LEN(SUBSTITUTE(TRIM(E24)," ",""))+1)
A25: 2.3-V | B25: V | C25: Entwickeln | D25: Ich durchdenke den Sinn bestehender digitaler Ressourcen und gestalte sie ggf. neu, um sie in interaktive, auf den Lernenden ausgerichtete Aktivitäten zu integrieren. Ich veröffentliche die Ressourcen (online) und mache sie so für die Lernenden und andere Lehrkräfte zugänglich (z. B. Anpassung digitaler Ressourcen und digital erweiterter Aufgaben in einem Online-Kurs, einer Online-Beurteilung, einem kollaborativen Online-Projekt, einem Wiki, einem Blog oder einem virtuellen Lernraum). | E25: Ich überarbeite Materialien für Lernende und stelle sie auch dem Kollegium zur Verfügung. | F25: =IF(LEN(TRIM(D25))=0,0,LEN(TRIM(D25))-LEN(SUBSTITUTE(TRIM(D25)," ",""))+1) | G25: =IF(LEN(TRIM(E25))=0,0,LEN(TRIM(E25))-LEN(SUBSTITUTE(TRIM(E25)," ",""))+1)
A26: 2.3-VI | B26: VI | C26: Weitergeben | D26: Ich erstelle innovative digitale Ressourcen selbst, lizenziere sie und veröffentliche sie für die Lernenden und andere Lehrkräfte (z. B. digital erweiterte Aufgaben in einem Online-Kurs, einer Online-Beurteilung, einem kollaborativen Online-Projekt oder einem virtuellen Lernraum). | E26: Ich veröffentliche eigene Materialien mit Lizenz, auch für Lehrpersonen anderer Schulen. | F26: =IF(LEN(TRIM(D26))=0,0,LEN(TRIM(D26))-LEN(SUBSTITUTE(TRIM(D26)," ",""))+1) | G26: =IF(LEN(TRIM(E26))=0,0,LEN(TRIM(E26))-LEN(SUBSTITUTE(TRIM(E26)," ",""))+1)

Sheet 3. Lehren und Lernen
A1: 3. Lehren und Lernen
A3: Item-ID | B3: Stufe | C3: Stufenbezeichnung | D3: Itemtext | E3: Kurzfassung (Entwurf SZ) | F3: Wörter heute | G3: Wörter Kurzfassung
A4: 3.1 Lehren | E4: Beispiele: Apps, Lernplattform, interaktive Wandtafel, Simulationen, Tools für die Zusammenarbeit
A5: 3.1-I | B5: I | C5: Einsteigen | D5: Ich bin mir bewusst, dass digitale Technologien wie beispielsweise Programme, Apps und cloudbasierte Ressourcen das Lehren und Lernen unterstützen und verbessern können, nutze diese Möglichkeit jedoch selten. | E5: Ich weiss, dass digitale Technologien den Unterricht unterstützen können, setze sie aber kaum ein. | F5: =IF(LEN(TRIM(D5))=0,0,LEN(TRIM(D5))-LEN(SUBSTITUTE(TRIM(D5)," ",""))+1) | G5: =IF(LEN(TRIM(E5))=0,0,LEN(TRIM(E5))-LEN(SUBSTITUTE(TRIM(E5)," ",""))+1)
A6: 3.1-II | B6: II | C6: Entdecken | D6: Ich versuche digitale Technologien wie beispielsweise Programme, mobile Apps und Tools, onlinebasierte Ressourcen oder interaktive Whiteboards zur Unterstützung oder Verbesserung meiner Unterrichtspraxis zu nutzen und die Lernenden zur Nutzung zu motivieren. | E6: Ich probiere einzelne digitale Werkzeuge im Unterricht aus. | F6: =IF(LEN(TRIM(D6))=0,0,LEN(TRIM(D6))-LEN(SUBSTITUTE(TRIM(D6)," ",""))+1) | G6: =IF(LEN(TRIM(E6))=0,0,LEN(TRIM(E6))-LEN(SUBSTITUTE(TRIM(E6)," ",""))+1)
A7: 3.1-III | B7: III | C7: Anwenden | D7: Ich verwende sach- und situationsgerecht verschiedene digitale Technologien, die innovative pädagogische Ansätze unterstützen können und die aktive Beteiligung der Lernenden an ihren Lernprozessen fördern. Diese umfassen z.B. problembasiertes Lernen, Selbstbewertung und Coaching durch andere Lernende. | E7: Digitale Technologien sind ein fester Bestandteil meines Unterrichts und aktivieren die Lernenden. | F7: =IF(LEN(TRIM(D7))=0,0,LEN(TRIM(D7))-LEN(SUBSTITUTE(TRIM(D7)," ",""))+1) | G7: =IF(LEN(TRIM(E7))=0,0,LEN(TRIM(E7))-LEN(SUBSTITUTE(TRIM(E7)," ",""))+1)
A8: 3.1-IV | B8: IV | C8: Integrieren | D8: Ich wähle digitale Technologien (z.B. Simulationen, interaktive Online-Tools und kollaborative Umgebungen) systematisch aus, um die Lernziele in meinen Lernkonzepten zu erreichen. | E8: Ich plane den Einsatz digitaler Technologien von den Lernzielen her. | F8: =IF(LEN(TRIM(D8))=0,0,LEN(TRIM(D8))-LEN(SUBSTITUTE(TRIM(D8)," ",""))+1) | G8: =IF(LEN(TRIM(E8))=0,0,LEN(TRIM(E8))-LEN(SUBSTITUTE(TRIM(E8)," ",""))+1)
A9: 3.1-V | B9: V | C9: Entwickeln | D9: Ich bewerte und gestalte den Einsatz digitaler Technologien zur flexiblen Anpassung von Lehrmethoden und innovativen Lernansätzen wie z.B. Coaching durch andere Lernende, Modellierung und Beratung. Ich berate mit Kolleginnen und Kollegen meine Strategien und gebe dieses Wissen im Kollegenkreis weiter. | E9: Ich überprüfe, was wirkt, und teile meine Erfahrungen im Kollegium. | F9: =IF(LEN(TRIM(D9))=0,0,LEN(TRIM(D9))-LEN(SUBSTITUTE(TRIM(D9)," ",""))+1) | G9: =IF(LEN(TRIM(E9))=0,0,LEN(TRIM(E9))-LEN(SUBSTITUTE(TRIM(E9)," ",""))+1)
A10: 3.1-VI | B10: VI | C10: Weitergeben | D10: Ich trage zur Entwicklung innovativer Lernpraktiken mit digitalen Technologien bei wie z.B. Online-Workshops, Co-Teaching und Reflexionsgespräche über die Wirksamkeit des Einsatzes digitaler Technologien. Diese gebe ich in regionalen und überregionalen Fortbildungen weiter. | E10: Ich gestalte neue Lernformen mit und gebe sie in Weiterbildungen weiter. | F10: =IF(LEN(TRIM(D10))=0,0,LEN(TRIM(D10))-LEN(SUBSTITUTE(TRIM(D10)," ",""))+1) | G10: =IF(LEN(TRIM(E10))=0,0,LEN(TRIM(E10))-LEN(SUBSTITUTE(TRIM(E10)," ",""))+1)
A12: 3.2 Lernbegleitung | E12: Beispiele: automatisches Feedback, Chat, Umfrage, gemeinsames Online-Dokument, Lernverlauf auf der Plattform
A13: 3.2-I | B13: I | C13: Einsteigen | D13: Ich bin mir bewusst, dass digitale Technologien dazu dienen können, Feedback zu geben und über Lehr- und Lernmethoden zu reflektieren, nutze diese Möglichkeit jedoch kaum oder gar nicht. | E13: Ich weiss, dass digitale Mittel beim Begleiten des Lernens helfen, nutze sie aber kaum. | F13: =IF(LEN(TRIM(D13))=0,0,LEN(TRIM(D13))-LEN(SUBSTITUTE(TRIM(D13)," ",""))+1) | G13: =IF(LEN(TRIM(E13))=0,0,LEN(TRIM(E13))-LEN(SUBSTITUTE(TRIM(E13)," ",""))+1)
A14: 3.2-II | B14: II | C14: Entdecken | D14: Ich versuche digitale Technologien zu nutzen, um den Lernenden Feedback und Unterstützung zu geben (z.B. automatisiertes Feedback, Links zu Online-Tutorials, Chat). | E14: Ich probiere digitale Wege aus, um Lernenden Feedback und Unterstützung zu geben. | F14: =IF(LEN(TRIM(D14))=0,0,LEN(TRIM(D14))-LEN(SUBSTITUTE(TRIM(D14)," ",""))+1) | G14: =IF(LEN(TRIM(E14))=0,0,LEN(TRIM(E14))-LEN(SUBSTITUTE(TRIM(E14)," ",""))+1)
A15: 3.2-III | B15: III | C15: Anwenden | D15: Ich verwende, je nach Anforderung, verschiedene digitale Technologien (z.B.Chats, Diskussionsforen und Umfragen im Unterricht) um den Lernenden ein Feedback zu geben und ihnen die Möglichkeit einzuräumen, über ihr Lernen nachzudenken. | E15: Ich gebe regelmässig digital Rückmeldung und lasse Lernende über ihr Lernen nachdenken. | F15: =IF(LEN(TRIM(D15))=0,0,LEN(TRIM(D15))-LEN(SUBSTITUTE(TRIM(D15)," ",""))+1) | G15: =IF(LEN(TRIM(E15))=0,0,LEN(TRIM(E15))-LEN(SUBSTITUTE(TRIM(E15)," ",""))+1)
A16: 3.2-IV | B16: IV | C16: Integrieren | D16: Ich setze digitale Technologien (z.B. gemeinsame Online-Dokumente, Aufzeichnungen von Lernaktivitäten und begleitete Reflexion) systematisch ein, um den Lernenden die Möglichkeit zu geben, eine Selbstbewertung durchzuführen und dadurch an der Gestaltung des Lernprozesses teilzuhaben. | E16: Ich setze digitale Mittel bewusst für die Selbsteinschätzung der Lernenden ein. | F16: =IF(LEN(TRIM(D16))=0,0,LEN(TRIM(D16))-LEN(SUBSTITUTE(TRIM(D16)," ",""))+1) | G16: =IF(LEN(TRIM(E16))=0,0,LEN(TRIM(E16))-LEN(SUBSTITUTE(TRIM(E16)," ",""))+1)
A17: 3.2-V | B17: V | C17: Entwickeln | D17: Ich analysiere und bewerte Lernen neu unter Berücksichtigung von Erkenntnissen, die durch digitale Technologien (z.B. Aufzeichnungen von Lernaktivitäten und Learning Analytics) gewonnen wurden. Ich berate mit Kolleginnen und Kollegen meine Strategien und gebe dieses Wissen im Kollegenkreis weiter. | E17: Ich werte digitale Lernspuren aus, passe meine Begleitung an und teile Erfahrungen im Kollegium. | F17: =IF(LEN(TRIM(D17))=0,0,LEN(TRIM(D17))-LEN(SUBSTITUTE(TRIM(D17)," ",""))+1) | G17: =IF(LEN(TRIM(E17))=0,0,LEN(TRIM(E17))-LEN(SUBSTITUTE(TRIM(E17)," ",""))+1)
A18: 3.2-VI | B18: VI | C18: Weitergeben | D18: Ich entwickle innovative Ansätze zur Unterstützung und Begleitung des Lernprozesses. Im Zuge dessen werden digitale Technologien (z.B. Diskussionsforen, gemeinsame Dokumente und FAQ-Sheets) eingesetzt. Diese gebe ich in regionalen und überregionalen Fortbildungen weiter. | E18: Ich entwickle neue Formen der Lernbegleitung und gebe sie in Weiterbildungen weiter. | F18: =IF(LEN(TRIM(D18))=0,0,LEN(TRIM(D18))-LEN(SUBSTITUTE(TRIM(D18)," ",""))+1) | G18: =IF(LEN(TRIM(E18))=0,0,LEN(TRIM(E18))-LEN(SUBSTITUTE(TRIM(E18)," ",""))+1)
A20: 3.3 Kollaboratives Lernen | E20: Beispiele: gemeinsame Online-Dokumente, Forum, Wiki, Projektplattform, virtueller Austausch
A21: 3.3-I | B21: I | C21: Einsteigen | D21: Ich bin mir bewusst, dass digitale Technologien genutzt werden können, um die Zusammenarbeit der Lernenden beim Lernen (z.B. im Rahmen von Online-Zusammenarbeit und der gemeinsamen Nutzung von Lernressourcen) zu fördern und zu verbessern, nutze diese Möglichkeit jedoch selten oder nicht. | E21: Ich weiss, dass digitale Mittel die Zusammenarbeit der Lernenden fördern, nutze sie aber selten. | F21: =IF(LEN(TRIM(D21))=0,0,LEN(TRIM(D21))-LEN(SUBSTITUTE(TRIM(D21)," ",""))+1) | G21: =IF(LEN(TRIM(E21))=0,0,LEN(TRIM(E21))-LEN(SUBSTITUTE(TRIM(E21)," ",""))+1)
A22: 3.3-II | B22: II | C22: Entdecken | D22: Ich versuche digitale Technologien (z.B. gemeinsame Dokumente und Beiträge in Foren) zur Unterstützung und Verbesserung kollaborativer Aktivitäten von Lernenden zu nutzen und die Lernenden dazu zu motivieren. | E22: Ich lasse Lernende ab und zu digital zusammenarbeiten, etwa in einem gemeinsamen Dokument. | F22: =IF(LEN(TRIM(D22))=0,0,LEN(TRIM(D22))-LEN(SUBSTITUTE(TRIM(D22)," ",""))+1) | G22: =IF(LEN(TRIM(E22))=0,0,LEN(TRIM(E22))-LEN(SUBSTITUTE(TRIM(E22)," ",""))+1)
A23: 3.3-III | B23: III | C23: Anwenden | D23: Ich verwende verschiedene digitale Technologien und Medien situationsgerecht (z.B. Foren, Wikis und kollaborative Lernprodukte), um das kollaborative Lernen zu unterstützen und zu verbessern. | E23: Lernende arbeiten in meinem Unterricht regelmässig digital zusammen. | F23: =IF(LEN(TRIM(D23))=0,0,LEN(TRIM(D23))-LEN(SUBSTITUTE(TRIM(D23)," ",""))+1) | G23: =IF(LEN(TRIM(E23))=0,0,LEN(TRIM(E23))-LEN(SUBSTITUTE(TRIM(E23)," ",""))+1)
A24: 3.3-IV | B24: IV | C24: Integrieren | D24: Ich wende digitale Technologien systematisch in meinen Lernkonzepten an, um das kollaborative Lernen zu verbessern und zu unterstützen (z.B. im Rahmen von Gruppenreflexion, Projektentwicklung und Austausch). | E24: Ich plane digitale Zusammenarbeit passend zu den Lernzielen meiner Einheiten. | F24: =IF(LEN(TRIM(D24))=0,0,LEN(TRIM(D24))-LEN(SUBSTITUTE(TRIM(D24)," ",""))+1) | G24: =IF(LEN(TRIM(E24))=0,0,LEN(TRIM(E24))-LEN(SUBSTITUTE(TRIM(E24)," ",""))+1)
A25: 3.3-V | B25: V | C25: Entwickeln | D25: Ich entwickle die Nutzung digitaler Technologien zum Wissensaufbau weiter (z.B. die gemeinsame Teilnahme an Projekten, der virtuelle Austausch und die Nutzung digitaler Tools für Kommunikation). Ich berate mit Kolleginnen und Kollegen meine Strategien und gebe dieses Wissen im Kollegenkreis weiter. | E25: Ich entwickle digitale Formen der Zusammenarbeit weiter und teile Erfahrungen im Kollegium. | F25: =IF(LEN(TRIM(D25))=0,0,LEN(TRIM(D25))-LEN(SUBSTITUTE(TRIM(D25)," ",""))+1) | G25: =IF(LEN(TRIM(E25))=0,0,LEN(TRIM(E25))-LEN(SUBSTITUTE(TRIM(E25)," ",""))+1)
A26: 3.3-VI | B26: VI | C26: Weitergeben | D26: Ich entwickle innovative Lernszenarien, indem ich Möglichkeiten der Zusammenarbeit zur Unterstützung des Lernens (z.B. Nutzung synchroner und asynchroner Online-Umgebungen sowie Mitgestaltung und gemeinsame Erstellung von Lernmaterial) anbiete. Diese gebe ich in regionalen und überregionalen Fortbildungen weiter. | E26: Ich gestalte neue kollaborative Lernszenarien und gebe sie in Weiterbildungen weiter. | F26: =IF(LEN(TRIM(D26))=0,0,LEN(TRIM(D26))-LEN(SUBSTITUTE(TRIM(D26)," ",""))+1) | G26: =IF(LEN(TRIM(E26))=0,0,LEN(TRIM(E26))-LEN(SUBSTITUTE(TRIM(E26)," ",""))+1)
A28: 3.4 Selbstgesteuertes Lernen | E28: Beispiele: digitaler Lernplan, Lernjournal, Fortschrittsanzeige, E-Portfolio, Lernplattform
A29: 3.4-I | B29: I | C29: Einsteigen | D29: Ich bin mir bewusst, dass digitale Technologien genutzt werden können, um aktives und autonomes Lernen (z.B. Planung, Zielsetzung und Aufzeichnung von Fortschritten) zu fördern, nutze diese Möglichkeit jedoch kaum oder gar nicht. | E29: Ich weiss, dass digitale Mittel selbstständiges Lernen fördern, nutze sie aber kaum. | F29: =IF(LEN(TRIM(D29))=0,0,LEN(TRIM(D29))-LEN(SUBSTITUTE(TRIM(D29)," ",""))+1) | G29: =IF(LEN(TRIM(E29))=0,0,LEN(TRIM(E29))-LEN(SUBSTITUTE(TRIM(E29)," ",""))+1)
A30: 3.4-II | B30: II | C30: Entdecken | D30: Ich versuche digitale Technologien zur Unterstützung der Lernenden bei der Planung ihres eigenen Lernens (z.B. in der Verwendung von digitalen Kalendern und Aufzeichnung von Fortschritten) zu nutzen und sie dazu zu motivieren. | E30: Ich probiere digitale Hilfen für die Lernplanung der Lernenden aus, etwa einen Lernplan. | F30: =IF(LEN(TRIM(D30))=0,0,LEN(TRIM(D30))-LEN(SUBSTITUTE(TRIM(D30)," ",""))+1) | G30: =IF(LEN(TRIM(E30))=0,0,LEN(TRIM(E30))-LEN(SUBSTITUTE(TRIM(E30)," ",""))+1)
A31: 3.4-III | B31: III | C31: Anwenden | D31: Ich verwende verschiedene digitale Technologien (z.B. Online-Lernumgebungen, Werkzeuge und Räume für die Zusammenarbeit) situationsgerecht, um die Lernenden bei der Planung und Steuerung ihres eigenen Lernens zu unterstützen. | E31: Lernende planen und steuern ihr Lernen regelmässig mit digitalen Mitteln. | F31: =IF(LEN(TRIM(D31))=0,0,LEN(TRIM(D31))-LEN(SUBSTITUTE(TRIM(D31)," ",""))+1) | G31: =IF(LEN(TRIM(E31))=0,0,LEN(TRIM(E31))-LEN(SUBSTITUTE(TRIM(E31)," ",""))+1)
A32: 3.4-IV | B32: IV | C32: Integrieren | D32: Ich wende digitale Technologien in meinen Lernkonzepten systematisch auf der Grundlage ihrer Eigenschaften an, um die selbstgesteuerten Lernfähigkeiten und die Autonomie der Lernenden zu steuern und zu fördern. Diese umfassen z.B. Eigeninitiative in Bezug auf das eigene Lernen, kreatives Eingehen auf neue Lernsituationen und Selbstreflexion, um den eigenen Fortschritt zu planen. | E32: Ich setze digitale Mittel bewusst ein, um Selbstständigkeit und Selbstreflexion zu fördern. | F32: =IF(LEN(TRIM(D32))=0,0,LEN(TRIM(D32))-LEN(SUBSTITUTE(TRIM(D32)," ",""))+1) | G32: =IF(LEN(TRIM(E32))=0,0,LEN(TRIM(E32))-LEN(SUBSTITUTE(TRIM(E32)," ",""))+1)
A33: 3.4-V | B33: V | C33: Entwickeln | D33: Ich gestalte digitale Technologien und passe diese an, damit sie von Lernenden zur Förderung ihres selbstgesteuerten Lernens eingesetzt werden, indem sie z.B. über ihre Lernstrategien reflektieren oder Lernergebnisse sammeln und teilen. Ich berate mit Kolleginnen und Kollegen meine Strategien und gebe dieses Wissen im Kollegenkreis weiter. | E33: Ich passe digitale Werkzeuge für selbstgesteuertes Lernen an und teile Erfahrungen im Kollegium. | F33: =IF(LEN(TRIM(D33))=0,0,LEN(TRIM(D33))-LEN(SUBSTITUTE(TRIM(D33)," ",""))+1) | G33: =IF(LEN(TRIM(E33))=0,0,LEN(TRIM(E33))-LEN(SUBSTITUTE(TRIM(E33)," ",""))+1)
A34: 3.4-VI | B34: VI | C34: Weitergeben | D34: Ich entwickle innovative pädagogischer Strategien und Praktiken für das selbstgesteuerte Lernen (z.B. Makerspaces und Lernräume mit digitalen Technologien). Diese gebe ich in regionalen und überregionalen Fortbildungen weiter. | E34: Ich entwickle neue Lernsettings für selbstgesteuertes Lernen und gebe sie weiter. | F34: =IF(LEN(TRIM(D34))=0,0,LEN(TRIM(D34))-LEN(SUBSTITUTE(TRIM(D34)," ",""))+1) | G34: =IF(LEN(TRIM(E34))=0,0,LEN(TRIM(E34))-LEN(SUBSTITUTE(TRIM(E34)," ",""))+1)

Sheet 4. Lerndiagnose und Feedback
A1: 4. Lerndiagnose und Feedback
A3: Item-ID | B3: Stufe | C3: Stufenbezeichnung | D3: Itemtext | E3: Kurzfassung (Entwurf SZ) | F3: Wörter heute | G3: Wörter Kurzfassung
A4: 4.1 Lernstandserhebung | E4: Beispiele: Quiz, Online-Umfrage, digitaler Test, Bewertungsraster, E-Portfolio, Peer-Feedback
A5: 4.1-I | B5: I | C5: Einsteigen | D5: Ich bin mir bewusst, dass es digitale Medien und Werkzeuge für die Lernstandserhebung gibt, nutze sie jedoch selten oder nie (z.B. digitale Quizze, Online-Umfragen). | E5: Ich weiss, dass es digitale Werkzeuge für Lernkontrollen gibt, verwende sie aber kaum. | F5: =IF(LEN(TRIM(D5))=0,0,LEN(TRIM(D5))-LEN(SUBSTITUTE(TRIM(D5)," ",""))+1) | G5: =IF(LEN(TRIM(E5))=0,0,LEN(TRIM(E5))-LEN(SUBSTITUTE(TRIM(E5)," ",""))+1)
A6: 4.1-II | B6: II | C6: Entdecken | D6: Ich setze digitale Medien für überwiegend traditionelle Formen der Lernstandserhebung ein (z.B. Textverarbeitungswerkzeuge, Tools zur Erzeugung von Online-Abfragen wie mobile Apps oder Spiele). | E6: Ich übertrage einzelne herkömmliche Lernkontrollen in digitale Form, etwa ein Quiz. | F6: =IF(LEN(TRIM(D6))=0,0,LEN(TRIM(D6))-LEN(SUBSTITUTE(TRIM(D6)," ",""))+1) | G6: =IF(LEN(TRIM(E6))=0,0,LEN(TRIM(E6))-LEN(SUBSTITUTE(TRIM(E6)," ",""))+1)
A7: 4.1-III | B7: III | C7: Anwenden | D7: Ich verwende verschiedene digitale Technologien zur Bewertung und passe diese bei Bedarf an (z. B. Erstellen eines digitalen Tests, Nutzung von Bewertungsplattformen, die den Schülern zeitnahes Feedback geben). | E7: Ich erfasse den Lernstand regelmässig mit verschiedenen digitalen Formen. | F7: =IF(LEN(TRIM(D7))=0,0,LEN(TRIM(D7))-LEN(SUBSTITUTE(TRIM(D7)," ",""))+1) | G7: =IF(LEN(TRIM(E7))=0,0,LEN(TRIM(E7))-LEN(SUBSTITUTE(TRIM(E7)," ",""))+1)
A8: 4.1-IV | B8: IV | C8: Integrieren | D8: Ich wähle digitale Technologien aus, um bestimmte Aspekte der Bewertung systematisch zu unterstützen und die Art des zu evaluierenden Lernergebnisses bestmöglich zu erfassen (z. B. Rubriken zur Selbstreflexion, Aufgaben, die den Lernenden zeitnahes Feedback bieten, gemeinsam genutzte Dokumente, die Peer-Reviews/Feedback unterstützen). | E8: Ich wähle die digitale Form danach aus, was genau ich erfassen will. | F8: =IF(LEN(TRIM(D8))=0,0,LEN(TRIM(D8))-LEN(SUBSTITUTE(TRIM(D8)," ",""))+1) | G8: =IF(LEN(TRIM(E8))=0,0,LEN(TRIM(E8))-LEN(SUBSTITUTE(TRIM(E8)," ",""))+1)
A9: 4.1-V | B9: V | C9: Entwickeln | D9: Ich wähle aus einer Vielzahl digitaler Bewertungstools und -formaten zur Lernstandserhebung kritisch aus, passe diese an und multipliziere sie im Kreis der Kolleginnen und Kollegen (z.B. e-Portfolios, Formate der Selbst- und Peerbewertung). | E9: Ich verbessere meine digitalen Bewertungsformen laufend und teile sie im Kollegium. | F9: =IF(LEN(TRIM(D9))=0,0,LEN(TRIM(D9))-LEN(SUBSTITUTE(TRIM(D9)," ",""))+1) | G9: =IF(LEN(TRIM(E9))=0,0,LEN(TRIM(E9))-LEN(SUBSTITUTE(TRIM(E9)," ",""))+1)
A10: 4.1-VI | B10: VI | C10: Weitergeben | D10: Ich entwickle neue digitale Bewertungsformate, die es auch ermöglichen, innovative pädagogische Ansätze und überfachliche Fertigkeiten bewerten zu können (z. B. Selbst- und Peer-Bewertung, digitale Test- und Diagnosesysteme, formative Assessments, e-Portfolios). Diese gebe ich in meinem Kollegium und in Fortbildungen weiter. | E10: Ich entwickle neue Bewertungsformen, auch für überfachliche Kompetenzen, und gebe sie weiter. | F10: =IF(LEN(TRIM(D10))=0,0,LEN(TRIM(D10))-LEN(SUBSTITUTE(TRIM(D10)," ",""))+1) | G10: =IF(LEN(TRIM(E10))=0,0,LEN(TRIM(E10))-LEN(SUBSTITUTE(TRIM(E10)," ",""))+1)
A12: 4.2 Analyse der Lernevidenz | E12: Beispiele: Quiz, Bearbeitungsstand auf der Lernplattform, Umfrage, Auswertung in Tabellen, Learning Analytics
A13: 4.2-I | B13: I | C13: Einsteigen | D13: Ich bin mir bewusst, dass die Effektivität von Lernprozessen auch mittels digitaler Medien analysiert werden kann, mache davon aber kaum oder gar keinen Gebrauch. | E13: Ich weiss, dass sich Lernprozesse digital auswerten lassen, mache davon aber kaum Gebrauch. | F13: =IF(LEN(TRIM(D13))=0,0,LEN(TRIM(D13))-LEN(SUBSTITUTE(TRIM(D13)," ",""))+1) | G13: =IF(LEN(TRIM(E13))=0,0,LEN(TRIM(E13))-LEN(SUBSTITUTE(TRIM(E13)," ",""))+1)
A14: 4.2-II | B14: II | C14: Entdecken | D14: Ich versuche, digitale Tools während des Unterrichts zu nutzen, um zeitnahes Feedback zur grundlegenden Beteiligung und Effektivität des Lernprozesses zu erhalten (z. B. digitale Quizze oder Abfragen, Online-Rückmeldung zum Bearbeitungsstand von Aufgaben). | E14: Ich probiere digitale Werkzeuge aus, um im Unterricht schnell den Lernstand zu sehen. | F14: =IF(LEN(TRIM(D14))=0,0,LEN(TRIM(D14))-LEN(SUBSTITUTE(TRIM(D14)," ",""))+1) | G14: =IF(LEN(TRIM(E14))=0,0,LEN(TRIM(E14))-LEN(SUBSTITUTE(TRIM(E14)," ",""))+1)
A15: 4.2-III | B15: III | C15: Anwenden | D15: Ich nutze regelmäßig digitale Tools und die Nutzungsdaten der Lernenden, um die Beteiligung und Effektivität der Lernprozesse zu beurteilen und zeitnah Feedback zum Lernverhalten geben zu können (z. B. Online-Umfragen, Formulare, Umfragen, Tabellenkalkulationen). | E15: Ich nutze regelmässig digitale Daten, um Beteiligung und Lernfortschritt einzuschätzen. | F15: =IF(LEN(TRIM(D15))=0,0,LEN(TRIM(D15))-LEN(SUBSTITUTE(TRIM(D15)," ",""))+1) | G15: =IF(LEN(TRIM(E15))=0,0,LEN(TRIM(E15))-LEN(SUBSTITUTE(TRIM(E15)," ",""))+1)
A16: 4.2-IV | B16: IV | C16: Integrieren | D16: Ich setze digitale Tools systematisch zur Datenerzeugung, -visualisierung und Analyse des Lernverhaltens der Lernenden ein, um zeitnah individuelles Feedback zur Lernentwicklung geben zu können (z. B. Tests, Beurteilungssysteme, Learning Analytics). | E16: Ich werte Lerndaten bewusst aus, um individuelle Rückmeldungen zu geben. | F16: =IF(LEN(TRIM(D16))=0,0,LEN(TRIM(D16))-LEN(SUBSTITUTE(TRIM(D16)," ",""))+1) | G16: =IF(LEN(TRIM(E16))=0,0,LEN(TRIM(E16))-LEN(SUBSTITUTE(TRIM(E16)," ",""))+1)
A17: 4.2-V | B17: V | C17: Entwickeln | D17: Ich analysiere und bewerte regelmäßig verschiedene Möglichkeiten der Nutzung digitaler Daten zur Optimierung des Lernprozesses und zur Anpassung eigener Lehrstrategien. Meine Kolleginnen und Kollegen unterstütze ich bei der Erhebung und Analyse digital erfasster Daten zum Lernprozess. | E17: Ich prüfe, welche Daten wirklich helfen, und unterstütze Kolleginnen und Kollegen dabei. | F17: =IF(LEN(TRIM(D17))=0,0,LEN(TRIM(D17))-LEN(SUBSTITUTE(TRIM(D17)," ",""))+1) | G17: =IF(LEN(TRIM(E17))=0,0,LEN(TRIM(E17))-LEN(SUBSTITUTE(TRIM(E17)," ",""))+1)
A18: 4.2-VI | B18: VI | C18: Weitergeben | D18: Ich initiiere und fördere in meiner Schule und ihrem Umfeld Strategien und Praktiken, die helfen, mittels Datengenerierung Lernprozesse zu beobachten. Mein diesbezügliches Wissen gebe ich in Kollegium und auf Fortbildungen weiter. | E18: Ich entwickle Vorgehensweisen zur Auswertung von Lerndaten und gebe sie weiter. | F18: =IF(LEN(TRIM(D18))=0,0,LEN(TRIM(D18))-LEN(SUBSTITUTE(TRIM(D18)," ",""))+1) | G18: =IF(LEN(TRIM(E18))=0,0,LEN(TRIM(E18))-LEN(SUBSTITUTE(TRIM(E18)," ",""))+1)
A20: 4.3 Feedback und Planung | E20: Beispiele: Online-Übungen mit automatischer Rückmeldung, digitale Kommentare, Peer-Feedback, Umfragen
A21: 4.3-I | B21: I | C21: Einsteigen | D21: Ich bin mir bewusst, dass digitale Technologien genutzt werden können, um Lernenden Feedback zu geben, mache davon aber noch keinen oder kaum Gebrauch (z. B. Online-Übungen, Online-Abfragen, automatisiertes Feedback). | E21: Ich weiss, dass ich digital Feedback geben kann, tue es aber kaum. | F21: =IF(LEN(TRIM(D21))=0,0,LEN(TRIM(D21))-LEN(SUBSTITUTE(TRIM(D21)," ",""))+1) | G21: =IF(LEN(TRIM(E21))=0,0,LEN(TRIM(E21))-LEN(SUBSTITUTE(TRIM(E21)," ",""))+1)
